[2024-06-18T19:24:29.413+0000] {local_task_job_runner.py:120} INFO - ::group::Pre task execution logs
[2024-06-18T19:24:29.455+0000] {taskinstance.py:2076} INFO - Dependencies all met for dep_context=non-requeueable deps ti=<TaskInstance: nba_data_pipeline.snowflake_create_stage scheduled__2024-06-17T00:00:00+00:00 [queued]>
[2024-06-18T19:24:29.464+0000] {taskinstance.py:2076} INFO - Dependencies all met for dep_context=requeueable deps ti=<TaskInstance: nba_data_pipeline.snowflake_create_stage scheduled__2024-06-17T00:00:00+00:00 [queued]>
[2024-06-18T19:24:29.464+0000] {taskinstance.py:2306} INFO - Starting attempt 2 of 2
[2024-06-18T19:24:29.477+0000] {taskinstance.py:2330} INFO - Executing <Task(SQLExecuteQueryOperator): snowflake_create_stage> on 2024-06-17 00:00:00+00:00
[2024-06-18T19:24:29.487+0000] {standard_task_runner.py:90} INFO - Running: ['***', 'tasks', 'run', 'nba_data_pipeline', 'snowflake_create_stage', 'scheduled__2024-06-17T00:00:00+00:00', '--job-id', '266', '--raw', '--subdir', 'DAGS_FOLDER/nba_news_stats_etl.py', '--cfg-path', '/tmp/tmp22awnd5v']
[2024-06-18T19:24:29.490+0000] {standard_task_runner.py:91} INFO - Job 266: Subtask snowflake_create_stage
[2024-06-18T19:24:29.490+0000] {logging_mixin.py:188} WARNING - /home/ubuntu/nba_ns_venv/lib/python3.12/site-packages/***/task/task_runner/standard_task_runner.py:61 DeprecationWarning: This process (pid=34751) is multi-threaded, use of fork() may lead to deadlocks in the child.
[2024-06-18T19:24:29.491+0000] {standard_task_runner.py:63} INFO - Started process 34759 to run task
[2024-06-18T19:24:29.585+0000] {task_command.py:426} INFO - Running <TaskInstance: nba_data_pipeline.snowflake_create_stage scheduled__2024-06-17T00:00:00+00:00 [running]> on host ip-172-31-45-144.ec2.internal
[2024-06-18T19:24:29.747+0000] {taskinstance.py:2648} INFO - Exporting env vars: AIRFLOW_CTX_DAG_OWNER='Airflow' AIRFLOW_CTX_DAG_ID='nba_data_pipeline' AIRFLOW_CTX_TASK_ID='snowflake_create_stage' AIRFLOW_CTX_EXECUTION_DATE='2024-06-17T00:00:00+00:00' AIRFLOW_CTX_TRY_NUMBER='2' AIRFLOW_CTX_DAG_RUN_ID='scheduled__2024-06-17T00:00:00+00:00'
[2024-06-18T19:24:29.749+0000] {taskinstance.py:430} INFO - ::endgroup::
[2024-06-18T19:24:29.762+0000] {sql.py:276} INFO - Executing: 
        CREATE OR REPLACE STAGE SNOW_S3_STAGE
        STORAGE_INTEGRATION = SNOW_S3
        URL = 's3://nba-stats-players/';
        
[2024-06-18T19:24:29.790+0000] {base.py:84} INFO - Using connection ID 'snowflake_conn' for task execution.
[2024-06-18T19:24:30.035+0000] {base.py:84} INFO - Using connection ID 'snowflake_conn' for task execution.
[2024-06-18T19:24:30.036+0000] {connection.py:399} INFO - Snowflake Connector for Python Version: 3.10.1, Python Version: 3.12.3, Platform: Linux-6.8.0-1009-aws-x86_64-with-glibc2.39
[2024-06-18T19:24:30.037+0000] {connection.py:1239} INFO - This connection is in OCSP Fail Open Mode. TLS Certificates would be checked for validity and revocation status. Any other Certificate Revocation related exceptions or OCSP Responder failures would be disregarded in favor of connectivity.
[2024-06-18T19:24:30.037+0000] {connection.py:1249} INFO - THIS CONNECTION IS IN INSECURE MODE. IT MEANS THE CERTIFICATE WILL BE VALIDATED BUT THE CERTIFICATE REVOCATION STATUS WILL NOT BE CHECKED.
[2024-06-18T19:24:30.100+0000] {ssl_wrap_socket.py:100} INFO - THIS CONNECTION IS IN INSECURE MODE. IT MEANS THE CERTIFICATE WILL BE VALIDATED BUT THE CERTIFICATE REVOCATION STATUS WILL NOT BE CHECKED.
[2024-06-18T19:24:30.355+0000] {cursor.py:1149} INFO - Number of results in first chunk: 1
[2024-06-18T19:24:30.356+0000] {sql.py:487} INFO - Running statement: CREATE OR REPLACE STAGE SNOW_S3_STAGE
        STORAGE_INTEGRATION = SNOW_S3
        URL = 's3://nba-stats-players/';, parameters: None
[2024-06-18T19:24:30.434+0000] {connection.py:762} INFO - closed
[2024-06-18T19:24:30.461+0000] {connection.py:768} INFO - No async queries seem to be running, deleting session
[2024-06-18T19:24:30.498+0000] {taskinstance.py:441} INFO - ::group::Post task execution logs
[2024-06-18T19:24:30.499+0000] {taskinstance.py:2905} ERROR - Task failed with exception
Traceback (most recent call last):
  File "/home/ubuntu/nba_ns_venv/lib/python3.12/site-packages/airflow/models/taskinstance.py", line 465, in _execute_task
    result = _execute_callable(context=context, **execute_callable_kwargs)
             ^^^^^^^^^^^^^^^^^^^^^^^^^^^^^^^^^^^^^^^^^^^^^^^^^^^^^^^^^^^^^
  File "/home/ubuntu/nba_ns_venv/lib/python3.12/site-packages/airflow/models/taskinstance.py", line 432, in _execute_callable
    return execute_callable(context=context, **execute_callable_kwargs)
           ^^^^^^^^^^^^^^^^^^^^^^^^^^^^^^^^^^^^^^^^^^^^^^^^^^^^^^^^^^^^
  File "/home/ubuntu/nba_ns_venv/lib/python3.12/site-packages/airflow/models/baseoperator.py", line 401, in wrapper
    return func(self, *args, **kwargs)
           ^^^^^^^^^^^^^^^^^^^^^^^^^^^
  File "/home/ubuntu/nba_ns_venv/lib/python3.12/site-packages/airflow/providers/common/sql/operators/sql.py", line 282, in execute
    output = hook.run(
             ^^^^^^^^^
  File "/home/ubuntu/nba_ns_venv/lib/python3.12/site-packages/airflow/providers/snowflake/hooks/snowflake.py", line 397, in run
    self._run_command(cur, sql_statement, parameters)  # type: ignore[attr-defined]
    ^^^^^^^^^^^^^^^^^^^^^^^^^^^^^^^^^^^^^^^^^^^^^^^^^
  File "/home/ubuntu/nba_ns_venv/lib/python3.12/site-packages/airflow/providers/common/sql/hooks/sql.py", line 492, in _run_command
    cur.execute(sql_statement)
  File "/home/ubuntu/nba_ns_venv/lib/python3.12/site-packages/snowflake/connector/cursor.py", line 1080, in execute
    Error.errorhandler_wrapper(self.connection, self, error_class, errvalue)
  File "/home/ubuntu/nba_ns_venv/lib/python3.12/site-packages/snowflake/connector/errors.py", line 290, in errorhandler_wrapper
    handed_over = Error.hand_to_other_handler(
                  ^^^^^^^^^^^^^^^^^^^^^^^^^^^^
  File "/home/ubuntu/nba_ns_venv/lib/python3.12/site-packages/snowflake/connector/errors.py", line 345, in hand_to_other_handler
    cursor.errorhandler(connection, cursor, error_class, error_value)
  File "/home/ubuntu/nba_ns_venv/lib/python3.12/site-packages/snowflake/connector/errors.py", line 221, in default_errorhandler
    raise error_class(
snowflake.connector.errors.ProgrammingError: 090105 (22000): 01b5190c-0001-e496-0006-023e00019272: Cannot perform CREATE STAGE. This session does not have a current database. Call 'USE DATABASE', or use a qualified name.
[2024-06-18T19:24:30.523+0000] {taskinstance.py:1206} INFO - Marking task as FAILED. dag_id=nba_data_pipeline, task_id=snowflake_create_stage, run_id=scheduled__2024-06-17T00:00:00+00:00, execution_date=20240617T000000, start_date=20240618T192429, end_date=20240618T192430
[2024-06-18T19:24:30.536+0000] {standard_task_runner.py:110} ERROR - Failed to execute job 266 for task snowflake_create_stage (090105 (22000): 01b5190c-0001-e496-0006-023e00019272: Cannot perform CREATE STAGE. This session does not have a current database. Call 'USE DATABASE', or use a qualified name.; 34759)
[2024-06-18T19:24:30.556+0000] {local_task_job_runner.py:240} INFO - Task exited with return code 1
[2024-06-18T19:24:30.596+0000] {taskinstance.py:3503} INFO - 0 downstream tasks scheduled from follow-on schedule check
[2024-06-18T19:24:30.601+0000] {local_task_job_runner.py:222} INFO - ::endgroup::
